An internal server error occurred
Traceback (most recent call last):
  File "/Users/AwotoroE-Dev/Desktop/DBMerge/.sense_env/lib/python3.11/site-packages/flask_restful/__init__.py", line 295, in error_router
    return self.handle_error(e)
           ^^^^^^^^^^^^^^^^^^^^
  File "/Users/AwotoroE-Dev/Desktop/DBMerge/.sense_env/lib/python3.11/site-packages/flask_restful/__init__.py", line 310, in handle_error
    _handle_flask_propagate_exceptions_config(current_app, e)
  File "/Users/AwotoroE-Dev/Desktop/DBMerge/.sense_env/lib/python3.11/site-packages/flask/app.py", line 1823, in full_dispatch_request
    rv = self.dispatch_request()
         ^^^^^^^^^^^^^^^^^^^^^^^
  File "/Users/AwotoroE-Dev/Desktop/DBMerge/.sense_env/lib/python3.11/site-packages/flask/app.py", line 1799, in dispatch_request
    return self.ensure_sync(self.view_functions[rule.endpoint])(**view_args)
           ^^^^^^^^^^^^^^^^^^^^^^^^^^^^^^^^^^^^^^^^^^^^^^^^^^^^^^^^^^^^^^^^^
  File "/Users/AwotoroE-Dev/Desktop/DBMerge/.sense_env/lib/python3.11/site-packages/flask_restful/__init__.py", line 489, in wrapper
    resp = resource(*args, **kwargs)
           ^^^^^^^^^^^^^^^^^^^^^^^^^
  File "/Users/AwotoroE-Dev/Desktop/DBMerge/.sense_env/lib/python3.11/site-packages/flask/views.py", line 107, in view
    return current_app.ensure_sync(self.dispatch_request)(**kwargs)
           ^^^^^^^^^^^^^^^^^^^^^^^^^^^^^^^^^^^^^^^^^^^^^^^^^^^^^^^^
  File "/Users/AwotoroE-Dev/Desktop/DBMerge/.sense_env/lib/python3.11/site-packages/flask_restful/__init__.py", line 604, in dispatch_request
    resp = meth(*args, **kwargs)
           ^^^^^^^^^^^^^^^^^^^^^
  File "/Users/AwotoroE-Dev/Desktop/DBMerge/src/Journals/views/data_controller.py", line 129, in get
    dataset = pd.read_csv(self.project_dir+"/results/ProcessedData.csv")
              ^^^^^^^^^^^^^^^^^^^^^^^^^^^^^^^^^^^^^^^^^^^^^^^^^^^^^^^^^^
  File "/Users/AwotoroE-Dev/Desktop/DBMerge/.sense_env/lib/python3.11/site-packages/pandas/io/parsers/readers.py", line 948, in read_csv
    return _read(filepath_or_buffer, kwds)
           ^^^^^^^^^^^^^^^^^^^^^^^^^^^^^^^
  File "/Users/AwotoroE-Dev/Desktop/DBMerge/.sense_env/lib/python3.11/site-packages/pandas/io/parsers/readers.py", line 611, in _read
    parser = TextFileReader(filepath_or_buffer, **kwds)
             ^^^^^^^^^^^^^^^^^^^^^^^^^^^^^^^^^^^^^^^^^^
  File "/Users/AwotoroE-Dev/Desktop/DBMerge/.sense_env/lib/python3.11/site-packages/pandas/io/parsers/readers.py", line 1448, in __init__
    self._engine = self._make_engine(f, self.engine)
                   ^^^^^^^^^^^^^^^^^^^^^^^^^^^^^^^^^
  File "/Users/AwotoroE-Dev/Desktop/DBMerge/.sense_env/lib/python3.11/site-packages/pandas/io/parsers/readers.py", line 1705, in _make_engine
    self.handles = get_handle(
                   ^^^^^^^^^^^
  File "/Users/AwotoroE-Dev/Desktop/DBMerge/.sense_env/lib/python3.11/site-packages/pandas/io/common.py", line 863, in get_handle
    handle = open(
             ^^^^^
FileNotFoundError: [Errno 2] No such file or directory: '/Users/AwotoroE-Dev/Desktop/DBMerge/src/Journals/results/ProcessedData.csv'
An internal server error occurred
Traceback (most recent call last):
  File "/Users/AwotoroE-Dev/Desktop/DBMerge/.sense_env/lib/python3.11/site-packages/flask_restful/__init__.py", line 295, in error_router
    return self.handle_error(e)
           ^^^^^^^^^^^^^^^^^^^^
  File "/Users/AwotoroE-Dev/Desktop/DBMerge/.sense_env/lib/python3.11/site-packages/flask_restful/__init__.py", line 310, in handle_error
    _handle_flask_propagate_exceptions_config(current_app, e)
  File "/Users/AwotoroE-Dev/Desktop/DBMerge/.sense_env/lib/python3.11/site-packages/flask/app.py", line 1823, in full_dispatch_request
    rv = self.dispatch_request()
         ^^^^^^^^^^^^^^^^^^^^^^^
  File "/Users/AwotoroE-Dev/Desktop/DBMerge/.sense_env/lib/python3.11/site-packages/flask/app.py", line 1799, in dispatch_request
    return self.ensure_sync(self.view_functions[rule.endpoint])(**view_args)
           ^^^^^^^^^^^^^^^^^^^^^^^^^^^^^^^^^^^^^^^^^^^^^^^^^^^^^^^^^^^^^^^^^
  File "/Users/AwotoroE-Dev/Desktop/DBMerge/.sense_env/lib/python3.11/site-packages/flask_restful/__init__.py", line 489, in wrapper
    resp = resource(*args, **kwargs)
           ^^^^^^^^^^^^^^^^^^^^^^^^^
  File "/Users/AwotoroE-Dev/Desktop/DBMerge/.sense_env/lib/python3.11/site-packages/flask/views.py", line 107, in view
    return current_app.ensure_sync(self.dispatch_request)(**kwargs)
           ^^^^^^^^^^^^^^^^^^^^^^^^^^^^^^^^^^^^^^^^^^^^^^^^^^^^^^^^
  File "/Users/AwotoroE-Dev/Desktop/DBMerge/.sense_env/lib/python3.11/site-packages/flask_restful/__init__.py", line 604, in dispatch_request
    resp = meth(*args, **kwargs)
           ^^^^^^^^^^^^^^^^^^^^^
  File "/Users/AwotoroE-Dev/Desktop/DBMerge/src/Journals/views/data_controller.py", line 129, in get
    dataset = pd.read_csv(self.project_dir+"/results/ProcessedData.csv")
              ^^^^^^^^^^^^^^^^^^^^^^^^^^^^^^^^^^^^^^^^^^^^^^^^^^^^^^^^^^
  File "/Users/AwotoroE-Dev/Desktop/DBMerge/.sense_env/lib/python3.11/site-packages/pandas/io/parsers/readers.py", line 948, in read_csv
    return _read(filepath_or_buffer, kwds)
           ^^^^^^^^^^^^^^^^^^^^^^^^^^^^^^^
  File "/Users/AwotoroE-Dev/Desktop/DBMerge/.sense_env/lib/python3.11/site-packages/pandas/io/parsers/readers.py", line 611, in _read
    parser = TextFileReader(filepath_or_buffer, **kwds)
             ^^^^^^^^^^^^^^^^^^^^^^^^^^^^^^^^^^^^^^^^^^
  File "/Users/AwotoroE-Dev/Desktop/DBMerge/.sense_env/lib/python3.11/site-packages/pandas/io/parsers/readers.py", line 1448, in __init__
    self._engine = self._make_engine(f, self.engine)
                   ^^^^^^^^^^^^^^^^^^^^^^^^^^^^^^^^^
  File "/Users/AwotoroE-Dev/Desktop/DBMerge/.sense_env/lib/python3.11/site-packages/pandas/io/parsers/readers.py", line 1705, in _make_engine
    self.handles = get_handle(
                   ^^^^^^^^^^^
  File "/Users/AwotoroE-Dev/Desktop/DBMerge/.sense_env/lib/python3.11/site-packages/pandas/io/common.py", line 863, in get_handle
    handle = open(
             ^^^^^
FileNotFoundError: [Errno 2] No such file or directory: '/Users/AwotoroE-Dev/Desktop/DBMerge/src/results/ProcessedData.csv'
An internal server error occurred
Traceback (most recent call last):
  File "/Users/AwotoroE-Dev/Desktop/DBMerge/.sense_env/lib/python3.11/site-packages/flask_restful/__init__.py", line 295, in error_router
    return self.handle_error(e)
           ^^^^^^^^^^^^^^^^^^^^
  File "/Users/AwotoroE-Dev/Desktop/DBMerge/.sense_env/lib/python3.11/site-packages/flask_restful/__init__.py", line 310, in handle_error
    _handle_flask_propagate_exceptions_config(current_app, e)
  File "/Users/AwotoroE-Dev/Desktop/DBMerge/.sense_env/lib/python3.11/site-packages/flask/app.py", line 1823, in full_dispatch_request
    rv = self.dispatch_request()
         ^^^^^^^^^^^^^^^^^^^^^^^
  File "/Users/AwotoroE-Dev/Desktop/DBMerge/.sense_env/lib/python3.11/site-packages/flask/app.py", line 1799, in dispatch_request
    return self.ensure_sync(self.view_functions[rule.endpoint])(**view_args)
           ^^^^^^^^^^^^^^^^^^^^^^^^^^^^^^^^^^^^^^^^^^^^^^^^^^^^^^^^^^^^^^^^^
  File "/Users/AwotoroE-Dev/Desktop/DBMerge/.sense_env/lib/python3.11/site-packages/flask_restful/__init__.py", line 489, in wrapper
    resp = resource(*args, **kwargs)
           ^^^^^^^^^^^^^^^^^^^^^^^^^
  File "/Users/AwotoroE-Dev/Desktop/DBMerge/.sense_env/lib/python3.11/site-packages/flask/views.py", line 107, in view
    return current_app.ensure_sync(self.dispatch_request)(**kwargs)
           ^^^^^^^^^^^^^^^^^^^^^^^^^^^^^^^^^^^^^^^^^^^^^^^^^^^^^^^^
  File "/Users/AwotoroE-Dev/Desktop/DBMerge/.sense_env/lib/python3.11/site-packages/flask_restful/__init__.py", line 604, in dispatch_request
    resp = meth(*args, **kwargs)
           ^^^^^^^^^^^^^^^^^^^^^
  File "/Users/AwotoroE-Dev/Desktop/DBMerge/src/Journals/views/data_controller.py", line 133, in get
    return row.to_json(orient='dict', default_handler=str)
           ^^^^^^^^^^^^^^^^^^^^^^^^^^^^^^^^^^^^^^^^^^^^^^^
  File "/Users/AwotoroE-Dev/Desktop/DBMerge/.sense_env/lib/python3.11/site-packages/pandas/core/generic.py", line 2629, in to_json
    return json.to_json(
           ^^^^^^^^^^^^^
  File "/Users/AwotoroE-Dev/Desktop/DBMerge/.sense_env/lib/python3.11/site-packages/pandas/io/json/_json.py", line 205, in to_json
    ).write()
      ^^^^^^^
  File "/Users/AwotoroE-Dev/Desktop/DBMerge/.sense_env/lib/python3.11/site-packages/pandas/io/json/_json.py", line 258, in write
    return ujson_dumps(
           ^^^^^^^^^^^^
ValueError: Invalid value 'dict' for option 'orient'
